<mujoco model="planar point mass">
  <include file="./common/skybox.xml"/>
  <include file="./common/visual.xml"/>
  <include file="./common/materials.xml"/>

  <option timestep="0.02">
  </option>

  <asset>  
      <material name="self2" rgba=".1 .2 0.075 1"/>
    </asset>

  <default>
    <joint type="hinge" axis="0 0 1" limited="true" range="-.29 .29" damping="1"/>
    <motor gear=".1" ctrlrange="-1 1" ctrllimited="true"/>
    <default class="wall">
      <geom type="box" material="site"/>
    </default>
  </default>

  <worldbody>
    <light name="light" pos="0 0 1"/>
    <camera name="fixed" pos="0 0 .75" quat="1 0 0 0"/>
    <geom name="ground" type="plane" pos="0 0 0" size=".075 .075 .025" material="grid"/>
    <geom name="wall_x" type="plane" pos="-0.075 0 .005" zaxis="1 0 0"  size=".005 .075 .005" material="decoration"/>
    <geom name="wall_y" type="plane" pos="0 -0.075 .005" zaxis="0 1 0"  size=".075 .005 .005" material="decoration"/>
    <geom name="wall_neg_x" type="plane" pos="0.075 0 .005" zaxis="-1 0 0"  size=".005 .075 .005" material="decoration"/>
    <geom name="wall_neg_y" type="plane" pos="0 0.075 .005" zaxis="0 -1 0"  size=".075 .005 .005" material="decoration"/>
      
    
    <geom name="maze_y" class="wall" pos="0 .0 .005" zaxis="0 1 0"  size=".045 .005 .005"/>
    <geom name="maze_x" class="wall" pos="0 .0 .005" zaxis="1 0 0"  size=".005 .045 .005"/>

    <body name="pointmass" pos="0 0 .0025">
      <camera name="cam0" pos="0 -0.075 0.075" xyaxes="1 0 0 0 0.7 0.7"/>
      <joint name="root_x" type="slide"  pos="0 0 0" axis="1 0 0" />
      <joint name="root_y" type="slide"  pos="0 0 0" axis="0 1 0" />
      <geom name="pointmass" type="sphere" size=".0025" material="self" mass="0.075"/>
    </body>

    <geom name="target" pos="0.0375 -0.0375 .0025" material="target" type="sphere" size=".00375" contype="0" conaffinity="0"/>
  </worldbody>

  <tendon>
    <fixed name="t1">
      <joint joint="root_x" coef="1"/>
      <joint joint="root_y" coef="0"/>
    </fixed>
    <fixed name="t2">
      <joint joint="root_x" coef="0"/>
      <joint joint="root_y" coef="1"/>
    </fixed>
  </tendon>

  <actuator>
    <motor name="t1" tendon="t1"/>
    <motor name="t2" tendon="t2"/>
  </actuator>
</mujoco>
